Workbook

Sheet 0. Documents list
B1: Color | C1: Meaning
C2: Milestones
C3: A project with multiple stakeholders
A6: # | B6: Name of the document | C6: Purpose | D6: Deadline | E6: Status | F6: Stakeholders | M6: R3 | O6: R4 | Q6: R5
F7: Responsible | G7: Reviewed by | H7: Users List (check note for full names) | M7: Date | N7: Changes | O7: Date | P7: Changes | Q7: Date | R7: Changes
A8: Stage 1: Market Entry & Partnerships
A9: 1 | E9: Completed
A10: 2 | E10: Completed
A11: 3 | E11: Cancelled
A12: 4 | E12: Completed
A13: 5 | E13: Completed
A14: 6 | E14: Completed
A15: 7 | E15: Cancelled
A16: 8 | E16: In progress
A17: 9 | E17: Completed
A18: 10 | E18: Completed
A19: 11 | E19: Completed
A20: 12 | E20: In progress
... A26: 18 | E26: In progress
B28: Gate 1 🔑 - decision to continue, change scope or cancel the project
A29: Stage 2: Financing & Preparation
A30: 19 | E30: Not started
A31: 20 | E31: Not started
A32: 21 | E32: Not started
A33: 22 | E33: Not started
A34: 23 | E34: Not started
A35: 24 | E35: Not started
A36: 25 | E36: Not started
A37: 26 | E37: Not started
A38: 27 | E38: Not started
A39: 28 | E39: Not started
B40: Gate 2 🔑 - decision to continue, change scope or cancel the project
A41: Stage 3: Factory Deployment & Operation
A42: 27
A43: 28 | E43: Not started
A44: 29 | E44: Not started
A45: 30 | E45: Not started
E46: Not started
A48: What other documents are used:

Sheet Success Criteria
A1: Before Project starts | E1: After Project is finished
A2: # | B2: Category | C2: Criteria | D2: Weight (sums to 1) | E2: Status | F2: Score (1–5) | G2: Notes | H2: Weighted Score
A3: 1 | B3: Timeline | C3: Project delivered on schedule | D3: 0.2 | E3: ✅
A4: 2 | B4: Budget | C4: Within approved budget | D4: 0.15 | E4: ✅
A5: 3 | B5: Quality Compliance | C5: Meets precast tolerance standards | D5: 0.2 | E5: ✅
A6: 4 | B6: HSE Compliance | C6: No major safety violations | D6: 0.1 | E6: ✅
A7: 5 | B7: Client Satisfaction | C7: Post-project client feedback | D7: 0.15 | E7: ✅
A8: 6 | B8: Logistics Efficiency | C8: Just-in-time deliveries without delays | D8: 0.1 | E8: ✅
A9: 7 | B9: Design Accuracy | C9: Shop drawings match as-built dimensions | D9: 0.1 | E9: ✅
G10: Total Project Score | H10: =SUM(H3:H9)
G11: Max score | H11: 5

Sheet 2. Supuestos & PL
B1: PlasHub — Supuestos & P&L Stage 1 | 12 Meses | Neo Amaru Global S.A.C.
B2: Azul=input | Negro=fórmula | Verde=link hoja | Fondo amarillo=supuesto crítico
B4: A. SUPUESTOS OPERATIVOS — Inputs (texto azul = modificable)
B5: Parámetro | C5: M1 | D5: M2 | E5: M3 | F5: M4 | G5: M5 | H5: M6 | I5: M7 | J5: M8 | K5: M9 | L5: M10 | M5: M11 | N5: M12
B6: Volumen recibido (ton/mes) | C6: 80 | D6: 80 | E6: 80 | F6: 80 | G6: 80 | H6: 80 | I6: 80 | J6: 80 | K6: 80 | L6: 80 | M6: 80 | N6: 80
B7: Precio compra ponderado ($/t) | C7: 190 | D7: 130 | E7: 130 | F7: 130 | G7: 130 | H7: 130 | I7: 130 | J7: 130 | K7: 130 | L7: 130 | M7: 130 | N7: 130
B8: Precio venta ponderado ($/t) | C8: 400 | D8: 248 | E8: 248 | F8: 248 | G8: 248 | H8: 248 | I8: 248 | J8: 248 | K8: 248 | L8: 248 | M8: 248 | N8: 248
B9: Flete inbound ($/t) + Logistica | C9: 75 | D9: 12 | E9: 12 | F9: 12 | G9: 12 | H9: 12 | I9: 12 | J9: 12 | K9: 12 | L9: 12 | M9: 12 | N9: 12
B10: Días ciclo de caja (pago→cobro) | C10: 45 | D10: 45 | E10: 45 | F10: 40 | G10: 40 | H10: 35 | I10: 35 | J10: 35 | K10: 30 | L10: 30 | M10: 30 | N10: 30
B12: B. OPEX FIJO MENSUAL — Inputs
B13: Concepto OPEX | C13: $/mes | D13: Descripción / nota
B14: Renta nave (subarrendamiento ~900 m²) | C14: =2700*1.18 | D14: Subarrendamiento Lima Norte $4,800–6,400/mes. Ref: ~$7/m² mercado industrial 2026.
B15: Salario Jefe de Planta / Site Manager | C15: 1100 | D15: Ing. industrial SENATI. Bruto S/4,500/mes ≈ $1,200 (incl. CTS y vacaciones).
B16: Salario operarios planta (×2) | C16: 1100 | D16: 2 operarios S/1,500/mes c/u. M1: considerar solo 1 si volumen < 50t.
B17: Electricidad 3-fase | C17: 350 | D17: ~900-1,500 kWh/mes. Tarifa industrial Lima: ~S/0.40/kWh ≈ $100-160. Buffer $350.
B18: Seguridad / vigilancia | C18: =400+700 | D18: Empresa seguridad S/1,500/mes. M1: CCTV+alarma alternativa.
B19: Mantenimiento equipos | C19: 50 | D19: Calibración báscula (S/200/año) + correctivo esporádico. Sin maquinaria pesada.
B20: Contabilidad / contador | C20: 500 | D20: Contador RMT S/800-1,200/mes. Incluye libros, SUNAT, planilla.
B21: EPP, útiles y consumibles | C21: 200 | D21: EPP S/300 + materiales registro S/200 = S/500/mes ≈ $135. Buffer $200.
B22: Comunicaciones (internet + móvil) | C22: 100 | D22: Internet industrial S/150 + móviles S/100 = S/250 ≈ $70. Buffer $100.
B23: Servicios Basicos | C23: 100
B24: Contingencia OPEX (5%) | C24: =ROUND(SUM(C14:C23)*0.05,0) | D24: Buffer 5% del OPEX base para imprevistos. No usar rutinariamente.
B25: TOTAL OPEX FIJO MENSUAL | C25: =SUM(C14:C24) | D25: Break-even (t/mes) = OPEX / Margen por tonelada — ver fórmula en sección C
B27: C. P&L MENSUAL — 12 MESES (fórmulas dinámicas)
B28: Concepto P&L | C28: M1 | D28: M2 | E28: M3 | F28: M4 | G28: M5 | H28: M6 | I28: M7 | J28: M8 | K28: M9 | L28: M10 | M28: M11 | N28: M12
B29: Ingresos por ventas ($) | C29: =C6*C8 | D29: =D6*D8 | E29: =E6*E8 | F29: =F6*F8 | G29: =G6*G8 | H29: =H6*H8 | I29: =I6*I8 | J29: =J6*J8 | ... N29: =N6*N8
B30: COGS — Compra de material ($) | C30: =-C6*C7 | D30: =-D6*D7 | E30: =-E6*E7 | F30: =-F6*F7 | G30: =-G6*G7 | H30: =-H6*H7 | I30: =-I6*I7 | J30: =-J6*J7 | ... N30: =-N6*N7
B31: Flete inbound ($) | C31: =-C6*C9 | D31: =-D6*D9 | E31: =-E6*E9 | F31: =-F6*F9 | G31: =-G6*G9 | H31: =-H6*H9 | I31: =-I6*I9 | J31: =-J6*J9 | ... N31: =-N6*N9
B32: MARGEN BRUTO ($) | C32: =C29+C30+C31 | D32: =D29+D30+D31 | E32: =E29+E30+E31 | F32: =F29+F30+F31 | G32: =G29+G30+G31 | H32: =H29+H30+H31 | I32: =I29+I30+I31 | J32: =J29+J30+J31 | ... N32: =N29+N30+N31
B33: % Margen bruto | C33: =IFERROR(C32/C29,0) | D33: =IFERROR(D32/D29,0) | E33: =IFERROR(E32/E29,0) | F33: =IFERROR(F32/F29,0) | G33: =IFERROR(G32/G29,0) | H33: =IFERROR(H32/H29,0) | I33: =IFERROR(I32/I29,0) | J33: =IFERROR(J32/J29,0) | ... N33: =IFERROR(N32/N29,0)
B34: OPEX fijo mensual ($) | C34: =-C25 | D34: =-C25 | E34: =-C25 | F34: =-C25 | G34: =-C25 | H34: =-C25 | I34: =-C25 | J34: =-C25 | K34: =-C25 | L34: =-C25 | M34: =-C25 | N34: =-C25
B35: EBITDA ($) | C35: =C32+C34 | D35: =D32+D34 | E35: =E32+E34 | F35: =F32+F34 | G35: =G32+G34 | H35: =H32+H34 | I35: =I32+I34 | J35: =J32+J34 | ... N35: =N32+N34
B36: EBITDA acumulado ($) | C36: =SUM($C$35:C35) | D36: =SUM($C$35:D35) | E36: =SUM($C$35:E35) | F36: =SUM($C$35:F35) | G36: =SUM($C$35:G35) | H36: =SUM($C$35:H35) | I36: =SUM($C$35:I35) | J36: =SUM($C$35:J35) | ... N36: =SUM($C$35:N35)
B37: Margen neto por tonelada ($/t) | C37: =IFERROR(C35/C6,0) | D37: =IFERROR(D35/D6,0) | E37: =IFERROR(E35/E6,0) | F37: =IFERROR(F35/F6,0) | G37: =IFERROR(G35/G6,0) | H37: =IFERROR(H35/H6,0) | I37: =IFERROR(I35/I6,0) | J37: =IFERROR(J35/J6,0) | ... N37: =IFERROR(N35/N6,0)
B38: Break-even (t/mes con params M1): | C38: =IFERROR(ROUND(C25/(C32/C6),0)&" t/mes","—") | D38: Con parámetros M1 (ajusta inputs arriba para sensibilizar)
B40: D. PAYBACK — Recuperación de Inversión Inicial
B41: Métrica | H41: Valor | K41: Nota
B42: Capital inicial invertido (CAPEX) | H42: ='1. Project Profile'!F33 | K42: Link al CAPEX del Project Profile. Se actualiza automáticamente.
B43: Capital disponible confirmado | H43: ='1. Project Profile'!F34 | K43: Link al capital disponible. Alex $15K + Raúl $5K (desde ago-2026).
B44: Gap de financiamiento | H44: ='1. Project Profile'!F35 | K44: Gap = Capital - CAPEX. Negativo = falta financiamiento. Ver opciones en Project Profile.
...

Sheet 3b. Flujo de Caja
B1: PlasHub — Flujo de Caja Mensual (Cash Flow) | 12 Meses
B2: El P&L muestra rentabilidad devengada. El Cash Flow muestra cuándo entra y sale dinero. El ciclo de caja (30-45 días) consume caja aunque el P&L sea positivo. [CORREGIDO v3: fila 14 'Pagos a proveedores' ahora usa el precio/flete del mes correspondiente; antes referenciaba la columna M1 para todos los meses, lo que inflaba el pago a -$21,200/mes y mostraba insolvencia falsa.]
B4: A. INPUTS (links automáticos desde hoja Supuestos & PL)
B5: Supuesto | C5: M1 | D5: M2 | E5: M3 | F5: M4 | G5: M5 | H5: M6 | I5: M7 | J5: M8 | K5: M9 | L5: M10 | M5: M11 | N5: M12
B6: Volumen (t/mes) | C6: ='2. Supuestos & PL'!C6 | D6: ='2. Supuestos & PL'!D6 | E6: ='2. Supuestos & PL'!E6 | F6: ='2. Supuestos & PL'!F6 | G6: ='2. Supuestos & PL'!G6 | H6: ='2. Supuestos & PL'!H6 | I6: ='2. Supuestos & PL'!I6 | J6: ='2. Supuestos & PL'!J6 | ... N6: ='2. Supuestos & PL'!N6
B7: Ingreso devengado ($) | C7: ='2. Supuestos & PL'!C29 | D7: ='2. Supuestos & PL'!D29 | E7: ='2. Supuestos & PL'!E29 | F7: ='2. Supuestos & PL'!F29 | G7: ='2. Supuestos & PL'!G29 | H7: ='2. Supuestos & PL'!H29 | I7: ='2. Supuestos & PL'!I29 | J7: ='2. Supuestos & PL'!J29 | ... N7: ='2. Supuestos & PL'!N29
B8: EBITDA devengado ($) | C8: ='2. Supuestos & PL'!C35 | D8: ='2. Supuestos & PL'!D35 | E8: ='2. Supuestos & PL'!E35 | F8: ='2. Supuestos & PL'!F35 | G8: ='2. Supuestos & PL'!G35 | H8: ='2. Supuestos & PL'!H35 | I8: ='2. Supuestos & PL'!I35 | J8: ='2. Supuestos & PL'!J35 | ... N8: ='2. Supuestos & PL'!N35
B9: Días ciclo de caja | C9: ='2. Supuestos & PL'!C10 | D9: ='2. Supuestos & PL'!D10 | E9: ='2. Supuestos & PL'!E10 | F9: ='2. Supuestos & PL'!F10 | G9: ='2. Supuestos & PL'!G10 | H9: ='2. Supuestos & PL'!H10 | I9: ='2. Supuestos & PL'!I10 | J9: ='2. Supuestos & PL'!J10 | ... N9: ='2. Supuestos & PL'!N10
B11: B. FLUJO DE CAJA MENSUAL — Incluye desfase ciclo de caja
B12: Concepto CF | C12: M1 | D12: M2 | E12: M3 | F12: M4 | G12: M5 | H12: M6 | I12: M7 | J12: M8 | K12: M9 | L12: M10 | M12: M11 | N12: M12
B13: Cobros efectivos (con desfase) | C13: =IF(C9<=30,C7,0) | D13: =IF(D9<=30,D7,C7) | E13: =IF(E9<=30,E7,D7) | F13: =IF(F9<=30,F7,E7) | G13: =IF(G9<=30,G7,F7) | H13: =IF(H9<=30,H7,G7) | I13: =IF(I9<=30,I7,H7) | J13: =IF(J9<=30,J7,I7) | K13: =IF(K9<=30,K7,J7) | ... N13: =IF(N9<=30,N7,M7)
B14: Pagos a proveedores (COGS+flete) | C14: =-C6*('2. Supuestos & PL'!C7+'2. Supuestos & PL'!C9) | D14: =-D6*('2. Supuestos & PL'!D7+'2. Supuestos & PL'!D9) | E14: =-E6*('2. Supuestos & PL'!E7+'2. Supuestos & PL'!E9) | F14: =-F6*('2. Supuestos & PL'!F7+'2. Supuestos & PL'!F9) | G14: =-G6*('2. Supuestos & PL'!G7+'2. Supuestos & PL'!G9) | H14: =-H6*('2. Supuestos & PL'!H7+'2. Supuestos & PL'!H9) | I14: =-I6*('2. Supuestos & PL'!I7+'2. Supuestos & PL'!I9) | J14: =-J6*('2. Supuestos & PL'!J7+'2. Supuestos & PL'!J9) | ... N14: =-N6*('2. Supuestos & PL'!N7+'2. Supuestos & PL'!N9)
B15: Pagos OPEX fijo (mes corriente) | C15: =-'2. Supuestos & PL'!C25 | D15: =-'2. Supuestos & PL'!C25 | E15: =-'2. Supuestos & PL'!C25 | F15: =-'2. Supuestos & PL'!C25 | G15: =-'2. Supuestos & PL'!C25 | H15: =-'2. Supuestos & PL'!C25 | I15: =-'2. Supuestos & PL'!C25 | J15: =-'2. Supuestos & PL'!C25 | K15: =-'2. Supuestos & PL'!C25 | L15: =-'2. Supuestos & PL'!C25 | M15: =-'2. Supuestos & PL'!C25 | N15: =-'2. Supuestos & PL'!C25
B16: Inversión inicial CAPEX (mes 0, mostrada en M1) | C16: =-'1. Project Profile'!F33 | D16: 0 | E16: 0 | F16: 0 | G16: 0 | H16: 0 | I16: 0 | J16: 0 | K16: 0 | L16: 0 | M16: 0 | N16: 0
B17: Flujo neto del mes ($) | C17: =C13+C14+C15 | D17: =D13+D14+D15 | E17: =E13+E14+E15 | F17: =F13+F14+F15 | G17: =G13+G14+G15 | H17: =H13+H14+H15 | I17: =I13+I14+I15 | J17: =J13+J14+J15 | ... N17: =N13+N14+N15
B18: Caja acumulada ($) | C18: =C16+C17 | D18: =C18+D17 | E18: =D18+E17 | F18: =E18+F17 | G18: =F18+G17 | H18: =G18+H17 | I18: =H18+I17 | J18: =I18+J17 | K18: =J18+K17 | ... N18: =M18+N17
B20: C. KPIs DE LIQUIDEZ
B21: Métrica | H21: Valor | K21: Nota
B22: Caja mínima (punto crítico) | H22: =MIN(C18:N18) | K22: Si más negativa que capital disponible ($22K): riesgo de insolvencia.
B23: Mes de caja mínima | H23: =IFERROR(MATCH(MIN(C18:N18),C18:N18,0),"—") | K23: Mes más crítico para la liquidez. Preparar colchón adicional ese mes.
B24: Caja al final del año (M12) | H24: =N18 | K24: Positivo = empresa auto-sostenible al cierre del año 1.
B25: Primer mes con flujo neto > 0 | H25: =IFERROR(MATCH(TRUE(),C17:N17>0,0),">12") | K25: Primer mes en que genera más caja de la que consume.

Sheet 4b. KPIs Operativos
B1: PlasHub — Dashboard KPIs Operativos | Seguimiento Semanal/Mensual
B2: Raúl puede llevar estos KPIs sin ser contador. Actualizar semanalmente en registro simple.
B4: KPI | C4: Frecuencia | D4: Fórmula de cálculo | E4: Objetivo / Alerta | F4: Fuente del dato | G4: Quién mide | H4: Acción si supera alerta
B5: Costo por tonelada almacenada ($/t) | C5: Semanal | D5: OPEX semana ÷ Toneladas en almacén | E5: Objetivo: $10-12/t ALERTA: > $15/t | F5: Inventario + banco | G5: Jefe de Planta | H5: Si > $15/t: revisar rotación. Material > 45 días → bajar precio para liquidar.
B6: Margen bruto por despacho (%) | C6: Por despacho | D6: (Precio venta − Precio compra) ÷ Precio venta | E6: Mínimo: 30% Objetivo: > 40% | F6: Factura compra + venta | G6: Raúl / Contador | H6: Si < 30%: revisar precio compra o renegociar precio venta. Escalar a Alex.
B7: Días de inventario por material | C7: Semanal | D7: Toneladas stock ÷ Toneladas recibidas/semana | E7: Objetivo: < 30 días ALERTA: > 45 días | F7: Libro EC-RS + báscula | G7: Jefe de Planta | H7: Si > 45 días: revisar demanda. Considerar mezcla o precio rebajado.
B8: Caja disponible vs. compromisos 30d ($) | C8: Semanal | D8: Saldo banco − Pagos comprometidos 30 días | E8: ALERTA: < $3,000 Crítico: < $1,500 | F8: Extracto bancario + facturas | G8: Raúl | H8: Si < $3,000: NO comprar material nuevo hasta cobrar. Activar cobro urgente.
B9: Costo flete inbound ($/t) | C9: Por camión | D9: Costo total flete ÷ Toneladas del viaje | E9: Objetivo: < $12/t ALERTA: > $18/t | F9: Factura transportista | G9: Warehouse Manager | H9: Si > $18/t: renegociar o consolidar viajes (menos camiones, más llenos).
B10: Tiempo ciclo proveedor→despacho (días) | C10: Por lote | D10: Fecha despacho − Fecha primera recepción del lote | E10: Objetivo: < 30 días ALERTA: > 45 días | F10: Libro EC-RS + nota entrega | G10: Jefe de Planta | H10: Si > 45 días: ¿consolidar con otro tipo? Revisar target 20 ton mínimo.
B11: Volumen mensual vs. target (%) | C11: Mensual | D11: Toneladas recibidas ÷ Target mensual × 100% | E11: Objetivo: ≥ 80% ALERTA: < 60% | F11: Libro EC-RS + pesadas | G11: Raúl | H11: Si < 60% por 2 meses: reunión urgente Alex + Raúl. Revisar fuentes alternativas.
B12: Tasa de rechazo por calidad (%) | C12: Por despacho | D12: Toneladas rechazadas ÷ Toneladas despachadas | E12: Stage 1: < 10% Stage 2: < 5% | F12: Reclamo cliente + nota devolución | G12: Jefe de Planta | H12: Si > 10%: revisar criterios clasificación y calificación de proveedores.

Sheet 5b. Modelo Comercial
B1: PlasHub — Modelo Comercial Interno | Roles, Precios y Distribución entre Socios
B2: Alex es simultáneamente proveedor, cliente y socio. Esta hoja define la estructura para evitar conflictos de precio y documenta acuerdos de governance.
B4: A. COMPARACIÓN DE MODELOS COMERCIALES
B5: Dimensión | C5: Modelo A — PlasHub compra y vende | D5: Modelo B — Fee de servicio/ton | E5: Veredicto A | F5: Veredicto B
B6: Descripción | C6: PlasHub compra a Alex a precio de mercado y vende al cliente. Captura margen completo. | D6: Alex vende al cliente. PlasHub cobra $15-35/ton por consolidar y despachar. | E6: ✅ Claro, trazable | F6: ⚠ Complejo
B7: Ingresos PlasHub (100 t/mes) | C7: 100t × $118/t = $11,800/mes margen bruto | D7: 100t × $25/t = $2,500/mes (fee) | E7: ✅ Cubre OPEX | F7: 🔴 No cubre OPEX
B8: ¿Cubre OPEX ~$9,100/mes? | C8: Sí — desde ~86 t/mes | D8: No — necesitaría >$36/t de fee | E8: ✅ | F8: 🔴 No viable Stage 1
B9: Compatibilidad EC-RS | C9: PlasHub es el comercializador. EC-RS aplica directamente. | D9: ¿Quién es el comercializador? Riesgo observación MINAM. | E9: ✅ Alineado con EC-RS | F9: ⚠ Revisar legal
B10: IGV en compras | C10: PlasHub recupera IGV de compras como crédito fiscal (régimen RMT). | D10: Sin compras propias. Sin crédito fiscal IGV. | E10: ✅ Beneficio fiscal | F10: ⚠ Sin beneficio
B11: Capital de trabajo | C11: Alto: paga al proveedor 30-45 días antes de cobrar al cliente. | D11: Bajo: no compra material. | E11: ⚠ Requiere capital | F11: ✅ Bajo riesgo
B12: Atractivo para inversores | C12: Alto: margen trading visible, modelo escalable a otros clientes. | D12: Bajo: márgenes mínimos, dependencia total de Alex. | E12: ✅ Preferido | F12: 🔴 Difícil financiar
B13: RECOMENDACIÓN FINAL | C13: ✅ MODELO RECOMENDADO para Stage 1 y Stage 2. | D13: ❌ No viable Stage 1. | E13: 🟢 IMPLEMENTAR | F13: 🔴 DESCARTAR
B16: B. GOVERNANCE Y DISTRIBUCIÓN ENTRE SOCIOS
B17: Aspecto | C17: Definición | D17: Justificación | E17: Documentación / acción requerida
B18: Participación accionaria | C18: Alex: 60% | Raúl: 40% | D18: Alex aporta $15K + flujo comercial. Raúl aporta operación y gestión del proyecto. | E18: Formalizar en Estatuto SAC ante SUNARP. Registrar antes de primera operación.
B19: Salario Raúl Stage 1 | C19: S/3,500–4,500/mes (desde EBITDA ≥ 0 por 2 meses consecutivos) | D19: No pagar salario antes de EBITDA positivo. Considera anticipo reembolsable. | E19: Incluir en pacto de socios: condición inicio salario.
B20: Precio de transferencia | C20: Precio de mercado verificable | D20: Alex → PlasHub: precio de mercado. NUNCA precio artificial. | E20: 🔴 RIESGO FISCAL: SUNAT ajusta precios entre partes vinculadas. Documentar con facturas de mercado.
B21: Dividendos | C21: Solo después de recuperar CAPEX | D21: No distribuir hasta EBITDA acumulado > CAPEX invertido. | E21: Formalizar en pacto de socios: reserva 30% utilidades para reinversión.
B22: Régimen tributario | C22: Régimen MYPE Tributario (RMT) | D22: Ventas año 1: $300-500K >> límite RER (~$140K). RMT obligatorio. | E22: 🔴 ACCIÓN INMEDIATA: verificar régimen en SUNAT. Cambiar a RMT ANTES de primera venta.
B23: Pacto de socios | C23: Documento notarial obligatorio | D23: Equity, política dividendos, precio transferencia, resolución conflictos. | E23: Costo: S/500-1,000 (notaría) + S/1,500-3,000 (abogado). Firmar antes de primera operación.

Sheet 1. Project Profile
B2: Stage 1 | H2: Stage 2 | N2: Stage 3
B3: Project Overview | H3: Project Overview | N3: Project Overview
B4: Project name | C4: Factory "Amaru I" – Planta Piloto Recolección y Procesamiento | E4: Project Manager | F4: Raúl | H4: Project name | I4: Factory "Amaru I" – Planta Piloto Recolección y Procesamiento | K4: Project Manager | L4: Raúl | N4: Project name | O4: Factory "Amaru I" – Planta Piloto Recolección y Procesamiento | Q4: Project Manager | R4: Raúl
B5: Location | C5: Perú | E5: Project Sponsor | F5: Alex (Owner) | H5: Location | I5: Perú | K5: Project Sponsor | L5: Alex (Owner) | N5: Location | O5: Perú | Q5: Project Sponsor | R5: Alex (Owner)
B6: Sector | C6: Reciclaje y Procesamiento de Plásticos Post‑Proceso | H6: Sector | I6: Reciclaje y Procesamiento de Plásticos Post‑Proceso | N6: Sector | O6: Reciclaje y Procesamiento de Plásticos Post‑Proceso
B7: Stages | C7: 1. Piloto – Planta de recolección + almacenamiento | H7: Stages | I7: 1. Piloto – Planta de recolección + almacenamiento | N7: Stages | O7: 1. Piloto – Planta de recolección + almacenamiento
C8: 2. Piloto – Planta de recolección + almacenamiento + Procesamiento | I8: 2. Piloto – Planta de recolección + almacenamiento + Procesamiento | O8: 2. Piloto – Planta de recolección + almacenamiento + Procesamiento
C9: 3. Escala a 5+ paises– Planta de recolección + almacenamiento + Procesamiento | I9: 3. Escala a 5+ paises– Planta de recolección + almacenamiento + Procesamiento | O9: 3. Escala a 5+ paises– Planta de recolección + almacenamiento + Procesamiento
B10: Project Summary | H10: Project Summary | N10: Project Summary
B11: Project Background: | C11: OPORTUNIDAD: Alex necesita un hub logístico para consolidar plásticos reciclados antes de exportar. SOLUCIÓN Stage 1 — PlasHub (consolidación pura, SIN procesamiento): RECIBE → CLASIFICA → PESA → ALMACENA → CONSOLIDA 20t → DESPACHA contenedor 40 pies. Capital confirmado: USD 22,000 (Alex $15K + Raúl $5K desde ago-2026). Zona nave: SMP / Los Olivos / Puente Piedra (Lima Norte). EC-RS (MINAM): CRÍTICO — 60-90 días — INICIAR INMEDIATAMENTE. Stage 1 NO incluye: trituración, lavado, peletizado ni maquinaria pesada. | H11: Project Background: | I11: Stage 1 ha validado: -Demanda de Alex: 500+ ton/mes confirmado (contrato MOU firmado) -Ubicación de terreno: Asegurada y verificada - Especificaciones técnicas: Layout y equipos definidos Modelo financiero: IRR 25–35% validado Permisos: Expediente EIA presentado a SENACE Objetivo de Stage 2: Ejecutar construcción de Fase 1, validar operación y preparar decisión de Fase 2. | N11: Project Background: | O11: Fase 1 validó: -Operación estable con volumen 400–500+ ton/mes -Márgenes de almacenaje 5–10 USD/ton mantenidos -Calidad controlada (rechazo < 10%) -Equipos y procesos optimizados Objetivo de Stage 3: Escalar planta a Fase 2 (6,000 m²), introducir procesamiento avanzado (trituración, lavado, peletizado) y diversificar clientes más allá de Alex.
B12: Agreed deliverables | H12: Agreed deliverables | N12: -
B13: Deliverable | D13: Responsable | E13: Due Date | F13: Status | H13: Deliverable | J13: Responsable | K13: Due Date | L13: Status | N13: Deliverable | P13: Responsable | Q13: Due Date | R13: Status
B14: Validación de mercado (demanda Alex + alternativas) | D14: Raúl | E14: 46081 | H14: Aprobación de permisos (EIA, municipal, INDECI, ITSE) | J14: Asesor
B15: Estudio técnico y de factibilidad (layout, CAPEX, especificaciones) | D15: Asesor Técnico | E15: 46081 | H15: Obra civil completada (nave, servicios, layout) | J15: Asesor
B16: Análisis legal/regulatorio (matriz permisos, EIA, INDECI) | D16: Asesor Legal | E16: 46075 | H16: Equipos principales procurados e instalados | J16: Alex
B17: Modelo financiero piloto (forecasts 24 meses, IRR, payback) | D17: Raúl | E17: 46086 | H17: Start of Production (SOP) – Fase 1 | J17: Site Manager
B18: MOU y acuerdos de gobernanza (roles, equity, CAPEX aportes) | D18: Raúl + Alex | E18: 46068 | H18: Operación 6–9 meses validando volumen, calidad, márgenes | J18: Site Manager
B19: Risk Register y planes de mitigación | D19: Raúl | E19: 46057 | F19: Progress | H19: KPIs de operación cumplidos (volumen, rechazo < 5%, margen 5–10 USD/ton) | J19: Site Manager
B20: Selección y aseguramiento de terreno | D20: Raúl + Alex | E20: 46075 | H20: Gate 2 Decision Report (Go/No-Go para Fase 2) | J20: Raúl
B21: Timelne | H21: Timelne | N21: Timelne
B22: Planned start: | C22: 46054 | E22: Planned end: | F22: 46086 | H22: Planned start: | I22: 46054 | K22: Planned end: | L22: 46086 | N22: Planned start: | O22: 46054 | Q22: Planned end: | R22: 46086
B23: Project cost - CAPEX por bloque | H23: Project cost - CAPEX por bloque | N23: Project cost - CAPEX por bloque
C24: Cost Component | D24: Breakdown / Notes | F24: Estimated USD | I24: Cost Component | J24: Breakdown / Notes | L24: Estimated USD | O24: Cost Component | P24: Breakdown / Notes | R24: Estimated USD
B25: Estudios y Asesoría | C25: Consultor EC-RS/ambiental (MINAM) | D25: EC-RS + Plan Manejo Residuos Sólidos | F25: 3500 | H25: CAPEX – Obra Civil | I25: Adecuación de terreno | J25: Limpieza, nivelación, servicios básicos | N25: Estudios y Asesoría
C26: Asesoría Legal (MOU + Licencia Funcionamiento) | D26: Notaría + abogado peruano | F26: 1500 | I26: Layout | J26: Estructura, techos, drenaje, pisos reforzados
C27: Ingeniería / diseño layout almacén | D27: Plano 7 zonas + flujos operativos | F27: 1000 | I27: Oficinas y servicios complementarios | J27: Oficina PM, laboratorio QA, baños, almacén herramientas
C28: Registro SUNAT + contabilidad inicial | D28: Cambio a RMT + contador 3 meses | F28: 1500 | H28: CAPEX – Equipos Principales | I28: Equipos de recepción/clasificación
B29: Viajes y Logística | C29: Depósito nave (1 mes negociado) | D29: ~900 m² Lima Norte. Negociar 1 mes vs. estándar 3. | F29: =8100*1.18 | I29: Equipos de almacenamiento | J29: Básculas, cintas transportadoras, screening | N29: Viajes y Logística
C30: Adecuaciones básicas nave | D30: Demarcación 7 zonas, señalética INDECI, luminarias | F30: 1500 | I30: Sistemas de control de calidad | J30: Equipos de medición, laboratorio QA básico
B31: Otros Costos | C31: Equipamiento operativo inicial | D31: Báscula 3t + 2 transpaletas + EPP | F31: 2300 | H31: CAPEX – Infraestructura | I31: Servicios (agua, energía, desagüe) | J31: Conexiones y acometidas | N31: Otros Costos
C32: Capital de trabajo ciclo de caja M1-M2 | D32: Pago proveedores antes de cobrar cliente (30-45 días) | F32: 0 | I32: Seguridad (CCTV, cercas, vigilancia) | J32: Sistemas de vigilancia y control de acceso
F33: =SUM(F25:F32) | H33: CAPEX – Softwares y Sistemas | I33: Sistema de gestión de inventario | J33: Software + implementación | R33: =SUM(R25:R32)
B34: ⚠ Análisis de Gap | C34: Capital disponible (Alex+Raúl) | D34: Alex ~$15K + Raúl ~$5K (desde ago-2026) | F34: 20000 | I34: Sistema de trazabilidad / tracking | J34: Integración con sistema Alex | N34: Decision Criteria
B35: GAP = Capital disponible − CAPEX Stage 1 | C35: Positivo = suficiente | Negativo = requiere financiamiento adicional | F35: =F34-F33 | H35: OPEX Stage 2 (primeros 18 meses) | I35: Nómina (Site Manager, supervisores, operadores, QA) | J35: ~15 personas, 18 meses | N35: 1. Strategic Impact
B36: ¿Apoya la estrategia LatAm del grupo? | F36: Grade (1-5) | I36: Servicios (agua, energía, internet, mantenimiento) | J36: Gastos operativos básicos | R36: Grade (1-5)
B37: Factory "Amaru I" es prueba de concepto para replicar en 5–7 países. Validar en Perú es crítico. | F37: 5 | I37: Seguros y compliance | J37: Pólizas integrales, permisos anuales | R37: 5
B38: ¿Refuerza la relación con el trader como cliente ancla? | F38: Grade (1-5) | I38: Capacitación y entrenamientos | J38: Programas internos + externos | R38: Grade (1-5)
B39: Planta resuelve problema estructural de Alex; lo "amarra" como cliente de largo plazo. | F39: 5 | I39: Contingencia (10% del CAPEX) | J39: Buffer para imprevistos | R39: 5
B40: ¿Genera aprendizaje industrial transferible? | F40: Grade (1-5) | R40: Grade (1-5)
B41: Procesos, layouts, sistemas operativos documentables y aplicables en otras plantas. | F41: 5 | H41: Decision Criteria | R41: 5
...

Sheet 3. Partner requirements
C2: Factory Requirements
C3: Category | D3: Responsible for req. | E3: Requirement | G3: Indoor / Outdoor facility Spec | H3: Outdoor Tent Spec | I3: Priority | J3: Notes / Scaling | K3: Facility Spec | L3: Notes | M3: Questions | N3: Setup Spec | O3: Notes
C24: Tab 2 – Equipment & Permits
C25: Category | D25: Responsible for req. | F25: Item | G25: Priority | H25: Notes | K25: Facility Spec | L25: Notes | M25: Questions | N25: Setup Spec | O25: Notes
C26: Equipment
C31: Permits
C37: Tab 3 – Material Requirements
C38: Category | F38: Item | G38: Priority | H38: Notes | K38: Facility Spec | L38: Notes | M38: Questions | N38: Setup Spec | O38: Notes
C39: Material
C47: Tab 4 – Factory area requirements
C48: Scenario (all double cell) | F48: Zones Included (Printing, Curing, Casting, Storage, etc) | G48: Zones Not Included (Lab, changing rooms, offices, etc.) | I48: Total Estimated Indoor Area Factory (sq m) | J48: Total Estimated Indoor Area On-site (sq m) | K48: Facility Spec (Indoor area) | L48: Notes | M48: Questions | N48: Facility Spec (Indoor area) | O48: Facility Spec (Outdoor area)
K55: Notes | N55: Notes
C61: Tab 5 – Alterations/changes needed to the facility
B62: No. | C62: Category | D62: Responsible for req. | E62: Location | F62: Description | G62: Priority | H62: Notes
B63: 1 | C63: Immediate modifications
B64: 2
B65: 3
B66: 4
B67: 5
B68: 6
B69: 7
B70: 8
B71: 9 | C71: Long term modifications
B72: 10
B73: 11
B74: 12
B75: 13
B76: 14
B77: 15
B78: 16
B79: 17
B80: 18
B81: 19
B82: 20
B83: 21

Sheet Timeline

Sheet Roles y Responsabilidades
A1: Rol | B1: Enfoque principal | C1: Responsabilidades clave | D1: Asignee | E1: Notes
A2: Project Manager | B2: Proyecto (Stage 1–2) | C2: Liderar planificación y ejecución del proyecto, cronograma y presupuesto; coordinar asesores (legal, ambiental, técnico, financiero); gestionar riesgos y reportar a socios. | D2: Raul
A3: Jefe de Planta / Site Manager | B3: Operación | C3: Gestionar operación diaria (recepción, almacenamiento, clasificación); cumplir KPIs de volumen, calidad y seguridad; liderar al equipo de planta y coordinar mantenimiento. | D3: Ingeniero industrial | E3: Uno egresado de la Senati o Una universidad de por ahi. De preferencia con experiencia en procesos industriales. O si no, el recien egresado necesitará de asesoria (Probablemente de Raul)
A4: Warehouse Manager | B4: Operación | C4: Planificar y coordinar recepción, almacenamiento e inventarios; organizar layout de almacén; supervisar operarios de bodega y asegurar trazabilidad de lotes. | D4: Jefe de almacen | E4: Una persona que pueda operar un montacarda de hasta 3 toneladas
A5: Agente Comercial | B5: Comercial | C5: Asegurar suministro mínimo (p.ej. 500+ ton/mes); cerrar contratos con clientes finales; definir precios y condiciones comerciales; actuar como “cliente ancla” y socio estratégico. | D5: Alex
A6: Responsable de Calidad (QA) | B6: Operación | C6: Definir y aplicar criterios de calidad; tomar muestras y registrar resultados; gestionar rechazos y reprocesos; apoyar implementación de sistemas de trazabilidad. | D6: Ingeniero industrial | E6: El mismo que Jefe de planta en la primera stage. Dependiendo de la escala en la segunda stage se necesitará de una persona totalmente dedicada a este rol
A7: Responsable HSE (Seguridad y Medio Ambiente) | B7: Operación | C7: Implementar normas de seguridad, EPP y procedimientos; capacitar al personal; supervisar cumplimiento ambiental en operación; gestionar incidentes y acciones correctivas. | D7: Ingeniero industrial | E7: El ingeniero industrial deberia tener un conocimiento en normas regulatorias de seguridad. Super importante incluir este rol en la descripcion del trabajo(JD) para el Jefe de planta
A8: Técnico de Mantenimiento | B8: Operación | C8: Ejecutar mantenimiento preventivo y correctivo de equipos (básculas, cintas, clasificación y, luego, trituración/lavado); gestionar repuestos; registrar historial de fallas. | D8: Un tecnico del Senati | E8: no es necesario full time, se le contrata para hacer un mantenimiento mensual, trimestral o dependiendo a las especi ficaciones de la maquinaria. Outsource Solo necesario en la segunda etapa.
A9: Supervisores de Turno | B9: Operación | C9: Coordinar al personal por turno; asignar tareas diarias; asegurar cumplimiento de procedimientos y estándares de seguridad; reportar incidencias a Jefe de Planta. | D9: Ingeniero industrial | E9: Entra en el rango de responsabilidades del Jefe de Planta
A10: Operarios de Planta y Almacén | B10: Operación | C10: Realizar carga/descarga, clasificación, limpieza, orden de almacén; operar equipos básicos; cumplir normas de seguridad y calidad. | D10: Operador de montacarga | E10: Un operador con almenos 2 años de experiencia en operacion con montacarga
A11: Jefe de Finanzas / CFO (puede ser part‑time) | B11: Finanzas | C11: Desarrollar y actualizar el modelo financiero; controlar CAPEX y OPEX; elaborar reportes mensuales a socios; gestionar flujo de caja y relación con bancos/inversores. | D11: Tigre en Finanzas. Outsource a una firma de consultoria
A12: Administración / RR.HH. | B12: Soporte | C12: Gestionar contrataciones, nómina y turnos; administrar documentación laboral; coordinar capacitaciones; apoyar en compras generales y servicios. | D12: No needed | E12: Este no es necesario al principio, normalmente se contrata a alguien asi cuando la empresa crece a mas de 20 personas
A13: Asesor Legal / Regulatorio | B13: Proyecto | C13: Tramitar y hacer seguimiento de permisos (EIA, municipal, INDECI, ITSE); estructurar contratos y MOU entre socios; asesorar en temas societarios y de compliance. | D13: Abogado | E13: Un abodago para revisar los contratos
A14: Asesor Ambiental (EIA) | B14: Proyecto | C14: Preparar y sustentar el EIA; definir requisitos ambientales de diseño (PTAR, manejo de residuos); acompañar monitoreo ambiental en operación inicial. | D14: Outsource o asesor ambiental. | E14: Lo que se necesita de esta persona es la elaboracion de reportes ambientales necesarios para las certificaciones y licencias
A15: Asesor Técnico / Ingeniería | B15: Proyecto | C15: Diseñar layout y especificaciones de equipos; apoyar selección de proveedores y contratos de obra/equipos; revisar propuestas técnicas y optimizaciones de proceso. | D15: Raul | E15: Cuando la planta inicie operaciones, yo me puedo hacer cargo de esto

Sheet Hoja 2
